<?xml version="1.0" ?>
<!-- =================================================================================== -->
<!-- |    This document was autogenerated by xacro from prbt_cell.urdf.xacro           | -->
<!-- |    EDITING THIS FILE BY HAND IS NOT RECOMMENDED                                 | -->
<!-- =================================================================================== -->
<robot name="prbt_cell">
  <!-- Specify some standard inertial calculations https://en.wikipedia.org/wiki/List_of_moments_of_inertia -->
  <!-- These make use of xacro's mathematical functionality -->
  <material name="aluminum">
    <color rgba="0.5 0.5 0.5 1"/>
  </material>
  <material name="plastic">
    <color rgba="0.1 0.1 0.1 1"/>
  </material>
  <!-- Add world link -->
  <link name="world"/>
  <material name="gray">
    <color rgba="0.6 0.8 0.8 1"/>
  </material>
  <link name="visuals_link">
    <visual>
      <geometry>
        <mesh filename="package://prbt_cell_description/meshes/prbt_cell_v1.0.STL" scale="0.001 0.001 0.001"/>
      </geometry>
      <material name="gray"/>
    </visual>
  </link>
  <link name="shield_front_link">
    <collision>
      <origin rpy="0 0 0" xyz="0 0 0"/>
      <geometry>
        <box size="1.2 0.045 1.16"/>
      </geometry>
      <material name="gray"/>
    </collision>
    <inertial>
      <origin rpy="0 0 0" xyz="0 0 0"/>
      <mass value="5"/>
      <inertia ixx="0.5615104166666666" ixy="0.0" ixz="0.0" iyy="1.1606666666666665" iyz="0.0" izz="0.6008437499999999"/>
    </inertial>
  </link>
  <link name="shield_rear_link">
    <collision>
      <origin rpy="0 0 0 " xyz="0 0 0"/>
      <geometry>
        <box size="1.2 0.09 1.16"/>
      </geometry>
      <material name="gray"/>
    </collision>
    <inertial>
      <origin rpy="0 0 0" xyz="0 0 0"/>
      <mass value="5"/>
      <inertia ixx="0.5640416666666666" ixy="0.0" ixz="0.0" iyy="1.1606666666666665" iyz="0.0" izz="0.6033749999999999"/>
    </inertial>
  </link>
  <link name="shield_right_link">
    <collision>
      <origin rpy="0 0 0" xyz="0 0 0"/>
      <geometry>
        <box size="0.045 0.8 1.16"/>
      </geometry>
      <material name="gray"/>
    </collision>
    <inertial>
      <origin rpy="0 0 0" xyz="0 0 0"/>
      <mass value="5"/>
      <inertia ixx="0.8273333333333333" ixy="0.0" ixz="0.0" iyy="0.5615104166666666" iyz="0.0" izz="0.2675104166666667"/>
    </inertial>
  </link>
  <link name="shield_left_link">
    <collision>
      <origin rpy="0 0 0" xyz="0 0 0"/>
      <geometry>
        <box size="0.045 0.8 1.16"/>
      </geometry>
      <material name="gray"/>
    </collision>
    <inertial>
      <origin rpy="0 0 0" xyz="0 0 0"/>
      <mass value="5"/>
      <inertia ixx="0.8273333333333333" ixy="0.0" ixz="0.0" iyy="0.5615104166666666" iyz="0.0" izz="0.2675104166666667"/>
    </inertial>
  </link>
  <link name="robotcell_base_link">
    <collision>
      <origin rpy="0 0 0" xyz="0 0 0.31"/>
      <geometry>
        <box size="1.2 0.8 0.62"/>
      </geometry>
      <material name="gray"/>
    </collision>
    <inertial>
      <origin rpy="0 0 0" xyz="0 0 0"/>
      <mass value="70"/>
      <inertia ixx="5.975666666666667" ixy="0.0" ixz="0.0" iyy="10.642333333333333" iyz="0.0" izz="12.133333333333333"/>
    </inertial>
  </link>
  <link name="robot_link"/>
  <joint name="robotcell_base_to_visual" type="fixed">
    <parent link="robotcell_base_link"/>
    <child link="visuals_link"/>
    <origin rpy="0 0 1.5707963267948966" xyz="0.6 -0.4 0"/>
  </joint>
  <joint name="robotcell_base_to_front_joint" type="fixed">
    <parent link="robotcell_base_link"/>
    <child link="shield_front_link"/>
    <origin rpy="0 0 0" xyz="0 0.3775 1.2"/>
  </joint>
  <joint name="robotcell_base_to_rear" type="fixed">
    <parent link="robotcell_base_link"/>
    <child link="shield_rear_link"/>
    <origin rpy="0 0 0" xyz="0 -0.35500000000000004 1.2"/>
  </joint>
  <joint name="robotcell_base_to_left" type="fixed">
    <parent link="robotcell_base_link"/>
    <child link="shield_left_link"/>
    <origin rpy="0 0 0" xyz="-0.5775 0 1.2"/>
  </joint>
  <joint name="robotcell_base_to_right" type="fixed">
    <parent link="robotcell_base_link"/>
    <child link="shield_right_link"/>
    <origin rpy="0 0 0" xyz="0.5775 0 1.2"/>
  </joint>
  <joint name="robot_cell_base_joint" type="fixed">
    <parent link="world"/>
    <child link="robotcell_base_link"/>
    <origin rpy="0 0 0" xyz="0 0 0"/>
  </joint>
  <joint name="robot_cell_base_to_robot_link" type="fixed">
    <parent link="robotcell_base_link"/>
    <child link="robot_link"/>
    <origin rpy="0 0 0" xyz="0.315 0.02 0.62"/>
  </joint>
  <!-- robot foot link -->
  <link name="prbt_base_link">
    <inertial>
      <mass value="2.4"/>
      <inertia ixx="0" ixy="0" ixz="0" iyy="0" iyz="0" izz="0"/>
    </inertial>
    <visual>
      <origin rpy="0 0 0" xyz="0 0 0"/>
      <geometry>
        <mesh filename="package://prbt_support/meshes/foot.dae"/>
      </geometry>
    </visual>
    <collision>
      <origin rpy="3.141592653589793 0 0" xyz="0 0 0.065"/>
      <geometry>
        <cylinder length="0.13" radius="0.09275"/>
      </geometry>
    </collision>
  </link>
  <!-- arm 1 joint -->
  <joint name="prbt_joint_1" type="revolute">
    <origin rpy="0 0 -3.141592653589793" xyz="0 0 0.2604"/>
    <parent link="prbt_base_link"/>
    <child link="prbt_link_1"/>
    <axis xyz="0 0 1"/>
    <limit effort="370" lower="-2.96706" upper="2.96706" velocity="1.57"/>
    <dynamics damping="15.0" friction="11"/>
  </joint>
  <!-- arm 1 link -->
  <link name="prbt_link_1">
    <inertial>
      <mass value="7.1"/>
      <origin xyz="0 -0.026 -0.051"/>
      <inertia ixx="3.53e-2" ixy="0" ixz="0" iyy="3.01e-2" iyz="9.04e-3" izz="1.87e-2"/>
    </inertial>
    <visual>
      <origin rpy="0 0 0" xyz="0 0 0"/>
      <geometry>
        <mesh filename="package://prbt_support/meshes/link_1.dae"/>
      </geometry>
    </visual>
    <collision>
      <origin rpy="0 0 0" xyz="0 0 -0.08"/>
      <geometry>
        <cylinder length="0.10" radius="0.07"/>
      </geometry>
    </collision>
    <collision>
      <origin rpy="0 0 0" xyz="0 0 0"/>
      <geometry>
        <sphere radius="0.09"/>
      </geometry>
    </collision>
    <collision>
      <origin rpy="0 1.5707963267948966 1.5707963267948966" xyz="0 -0.10 0"/>
      <geometry>
        <cylinder length="0.10" radius="0.065"/>
      </geometry>
    </collision>
  </link>
  <!-- joint between arm_1_link and arm_2_link -->
  <joint name="prbt_joint_2" type="revolute">
    <origin rpy="1.5707963267948966 0 0" xyz="0 0 0"/>
    <parent link="prbt_link_1"/>
    <child link="prbt_link_2"/>
    <axis xyz="0 0 1"/>
    <limit effort="370" lower="-2.53073" upper="2.53073" velocity="1.57"/>
    <dynamics damping="12.0" friction="10.0"/>
  </joint>
  <link name="prbt_link_2">
    <inertial>
      <mass value="1.7"/>
      <origin xyz="0 0.162 0.134"/>
      <inertia ixx="3.58e-2" ixy="0" ixz="0" iyy="3.22e-3" iyz="-1.45e-3" izz="3.66e-2"/>
    </inertial>
    <visual name="first">
      <origin rpy="0 0 0" xyz="0 0 0"/>
      <geometry>
        <mesh filename="package://prbt_support/meshes/link_2.dae"/>
      </geometry>
    </visual>
    <collision>
      <origin rpy="0.17453292519943295 0 0" xyz="0 0.15 0.145"/>
      <geometry>
        <box size="0.121 0.27 0.065"/>
      </geometry>
    </collision>
    <collision>
      <origin rpy="-0.4487989505128276 0 0" xyz="0 0.3 0.145"/>
      <geometry>
        <box size="0.11 0.1 0.075"/>
      </geometry>
    </collision>
  </link>
  <!-- joint between arm_2_link and arm_3_link -->
  <joint name="prbt_joint_3" type="revolute">
    <origin rpy="0 3.141592653589793 0" xyz="0 0.35 0"/>
    <parent link="prbt_link_2"/>
    <child link="prbt_link_3"/>
    <axis xyz="0 0 1"/>
    <limit effort="176" lower="-2.35620" upper="2.35620" velocity="1.57"/>
    <dynamics damping="4.5" friction="4.5"/>
  </joint>
  <link name="prbt_link_3">
    <inertial>
      <mass value="4.8"/>
      <origin xyz="0 0.043 -0.027"/>
      <inertia ixx="2.06e-2" ixy="0" ixz="0" iyy="1.08e-2" iyz="-5.36e-3" izz="1.63e-2"/>
    </inertial>
    <visual>
      <origin rpy="0 0 0" xyz="0 0 0"/>
      <geometry>
        <mesh filename="package://prbt_support/meshes/link_3.dae"/>
      </geometry>
    </visual>
    <collision>
      <origin rpy="0 0 0" xyz="0 0 -0.11"/>
      <geometry>
        <cylinder length="0.10" radius="0.06"/>
      </geometry>
    </collision>
    <collision>
      <origin rpy="0 0 0" xyz="0 0 0"/>
      <geometry>
        <sphere radius="0.085"/>
      </geometry>
    </collision>
    <collision>
      <origin rpy="0 1.5707963267948966 1.5707963267948966" xyz="0 0.10 0"/>
      <geometry>
        <cylinder length="0.10" radius="0.065"/>
      </geometry>
    </collision>
  </link>
  <!-- joint between arm_3_link and arm_4_link -->
  <joint name="prbt_joint_4" type="revolute">
    <origin rpy="-1.5707963267948966 3.141592653589793 0" xyz="0 0 0"/>
    <parent link="prbt_link_3"/>
    <child link="prbt_link_4"/>
    <axis xyz="0 0 1"/>
    <limit effort="176" lower="-2.96706" upper="2.96706" velocity="1.57"/>
    <dynamics damping="4.2" friction="3.8"/>
  </joint>
  <link name="prbt_link_4">
    <inertial>
      <mass value="0.9"/>
      <origin xyz="0 -0.061 0.204"/>
      <inertia ixx="6.79e-3" ixy="0" ixz="0" iyy="4.91e-3" iyz="2.67e-3" izz="3.40e-3"/>
    </inertial>
    <visual>
      <origin rpy="0 0 0" xyz="0 0 0"/>
      <geometry>
        <mesh filename="package://prbt_support/meshes/link_4.dae"/>
      </geometry>
    </visual>
    <collision>
      <origin rpy="0.966643893412244 0 0" xyz="0 -0.04 0.162"/>
      <geometry>
        <box size="0.121 0.08 0.17"/>
      </geometry>
    </collision>
    <collision>
      <origin rpy="-0.10471975511965977 0 0" xyz="0 -0.115 0.25"/>
      <geometry>
        <box size="0.09 0.06 0.12"/>
      </geometry>
    </collision>
  </link>
  <!-- joint between arm_4_link and arm_5_link -->
  <joint name="prbt_joint_5" type="revolute">
    <origin rpy="1.5707963267948966 0 3.141592653589793" xyz="0 0 0.307"/>
    <parent link="prbt_link_4"/>
    <child link="prbt_link_5"/>
    <axis xyz="0 0 1"/>
    <limit effort="41.6" lower="-2.96706" upper="2.96706" velocity="1.57"/>
    <dynamics damping="1.5" friction="3.5"/>
  </joint>
  <link name="prbt_link_5">
    <inertial>
      <mass value="2.6"/>
      <origin xyz="-0.001 0.021 -0.032"/>
      <inertia ixx="7.37e-3" ixy="4.78e-6" ixz="6.00e-5" iyy="5.87e-3" iyz="-1.71e-3" izz="3.96e-3"/>
    </inertial>
    <visual>
      <origin rpy="0 0 0" xyz="0 0 0"/>
      <geometry>
        <mesh filename="package://prbt_support/meshes/link_5.dae"/>
      </geometry>
    </visual>
    <collision>
      <origin rpy="0 0 0" xyz="0 0 -0.095"/>
      <geometry>
        <cylinder length="0.08" radius="0.045"/>
      </geometry>
    </collision>
    <collision>
      <origin rpy="0 0 0" xyz="0 0 -0.06"/>
      <geometry>
        <cylinder length="0.04" radius="0.0545"/>
      </geometry>
    </collision>
    <collision>
      <origin rpy="0 0 0" xyz="0 0 0"/>
      <geometry>
        <sphere radius="0.07"/>
      </geometry>
    </collision>
    <collision>
      <origin rpy="0 1.5707963267948966 1.5707963267948966" xyz="0 0.05 0"/>
      <geometry>
        <cylinder length="0.03" radius="0.05"/>
      </geometry>
    </collision>
    <collision>
      <origin rpy="0 1.5707963267948966 1.5707963267948966" xyz="0 0.05 0"/>
      <geometry>
        <cylinder length="0.049" radius="0.0435"/>
      </geometry>
    </collision>
  </link>
  <!-- joint between arm_5_link and flange -->
  <joint name="prbt_joint_6" type="revolute">
    <origin rpy="-1.5707963267948966 0 0" xyz="0 0.084 0"/>
    <parent link="prbt_link_5"/>
    <child link="prbt_flange"/>
    <axis xyz="0 0 1"/>
    <limit effort="20.1" lower="-3.12414" upper="3.12414" velocity="1.57"/>
    <dynamics damping="4.5" friction="7.0"/>
  </joint>
  <!-- Flange -->
  <link name="prbt_flange">
    <inertial>
      <mass value="0.02"/>
      <origin xyz="0 0 0"/>
      <inertia ixx="0" ixy="0" ixz="0" iyy="0" iyz="0" izz="0"/>
    </inertial>
    <visual>
      <origin rpy="0 0 0" xyz="0 0 0"/>
      <geometry>
        <mesh filename="package://prbt_support/meshes/flange.dae"/>
      </geometry>
    </visual>
    <collision>
      <origin rpy="0 0 0" xyz="0 0 -0.0035"/>
      <geometry>
        <cylinder length="0.02" radius="0.0331"/>
      </geometry>
    </collision>
  </link>
  <!-- ROS-Industrial 'base' frame: base_link to robot world coordinate sytem transform -->
  <link name="prbt_base"/>
  <joint name="prbt_base_link-base" type="fixed">
    <origin rpy="0 0 0" xyz="0 0 0"/>
    <parent link="prbt_base_link"/>
    <child link="prbt_base"/>
  </joint>
  <!-- ROS-Industrial 'tool0' frame: all-zeros tool frame -->
  <link name="prbt_tool0"/>
  <joint name="prbt_flange-tool0" type="fixed">
    <origin rpy="0 0 0" xyz="0 0 0"/>
    <parent link="prbt_flange"/>
    <child link="prbt_tool0"/>
  </joint>
  <!-- transmissions for gazebo -->
  <transmission name="prbt_joint_1_trans">
    <type>transmission_interface/SimpleTransmission</type>
    <joint name="prbt_joint_1">
      <hardwareInterface>hardware_interface/PositionJointInterface</hardwareInterface>
    </joint>
    <actuator name="prbt_joint_1_motor"/>
  </transmission>
  <transmission name="prbt_joint_2_trans">
    <type>transmission_interface/SimpleTransmission</type>
    <joint name="prbt_joint_2">
      <hardwareInterface>hardware_interface/PositionJointInterface</hardwareInterface>
    </joint>
    <actuator name="prbt_joint_2_motor"/>
  </transmission>
  <transmission name="prbt_joint_3_trans">
    <type>transmission_interface/SimpleTransmission</type>
    <joint name="prbt_joint_3">
      <hardwareInterface>hardware_interface/PositionJointInterface</hardwareInterface>
    </joint>
    <actuator name="prbt_joint_3_motor"/>
  </transmission>
  <transmission name="prbt_joint_4_trans">
    <type>transmission_interface/SimpleTransmission</type>
    <joint name="prbt_joint_4">
      <hardwareInterface>hardware_interface/PositionJointInterface</hardwareInterface>
    </joint>
    <actuator name="prbt_joint_4_motor"/>
  </transmission>
  <transmission name="prbt_joint_5_trans">
    <type>transmission_interface/SimpleTransmission</type>
    <joint name="prbt_joint_5">
      <hardwareInterface>hardware_interface/PositionJointInterface</hardwareInterface>
    </joint>
    <actuator name="prbt_joint_5_motor"/>
  </transmission>
  <transmission name="prbt_joint_6_trans">
    <type>transmission_interface/SimpleTransmission</type>
    <joint name="prbt_joint_6">
      <hardwareInterface>hardware_interface/PositionJointInterface</hardwareInterface>
    </joint>
    <actuator name="prbt_joint_6_motor"/>
  </transmission>
  <gazebo>
    <plugin filename="libgazebo_ros_control.so" name="gazebo_ros_control">
      <robotNamespace>prbt</robotNamespace>
      <robotSimType>gazebo_ros_control/DefaultRobotHWSim</robotSimType>
      <legacyModeNS>false</legacyModeNS>
      <!-- Only used from ros-kinetic-gazebo-ros-control 2.5.18 -->
    </plugin>
  </gazebo>
  <gazebo reference="prbt_joint_1">
    <provideFeedback>true</provideFeedback>
  </gazebo>
  <gazebo>
    <plugin filename="libgazebo_ros_ft_sensor.so" name="ft_sensor">
      <updateRate>100.0</updateRate>
      <topicName>prbt/ft_sensor/joint_1</topicName>
      <jointName>prbt_joint_1</jointName>
    </plugin>
  </gazebo>
  <gazebo reference="prbt_joint_2">
    <provideFeedback>true</provideFeedback>
  </gazebo>
  <gazebo>
    <plugin filename="libgazebo_ros_ft_sensor.so" name="ft_sensor">
      <updateRate>100.0</updateRate>
      <topicName>prbt/ft_sensor/joint_2</topicName>
      <jointName>prbt_joint_2</jointName>
    </plugin>
  </gazebo>
  <gazebo reference="prbt_joint_3">
    <provideFeedback>true</provideFeedback>
  </gazebo>
  <gazebo>
    <plugin filename="libgazebo_ros_ft_sensor.so" name="ft_sensor">
      <updateRate>100.0</updateRate>
      <topicName>prbt/ft_sensor/joint_3</topicName>
      <jointName>prbt_joint_3</jointName>
    </plugin>
  </gazebo>
  <gazebo reference="prbt_joint_4">
    <provideFeedback>true</provideFeedback>
  </gazebo>
  <gazebo>
    <plugin filename="libgazebo_ros_ft_sensor.so" name="ft_sensor">
      <updateRate>100.0</updateRate>
      <topicName>prbt/ft_sensor/joint_4</topicName>
      <jointName>prbt_joint_4</jointName>
    </plugin>
  </gazebo>
  <gazebo reference="prbt_joint_5">
    <provideFeedback>true</provideFeedback>
  </gazebo>
  <gazebo>
    <plugin filename="libgazebo_ros_ft_sensor.so" name="ft_sensor">
      <updateRate>100.0</updateRate>
      <topicName>prbt/ft_sensor/joint_5</topicName>
      <jointName>prbt_joint_5</jointName>
    </plugin>
  </gazebo>
  <gazebo reference="prbt_joint_6">
    <provideFeedback>true</provideFeedback>
  </gazebo>
  <gazebo>
    <plugin filename="libgazebo_ros_ft_sensor.so" name="ft_sensor">
      <updateRate>100.0</updateRate>
      <topicName>prbt/ft_sensor/joint_6</topicName>
      <jointName>prbt_joint_6</jointName>
    </plugin>
  </gazebo>
  <joint name="prbt_base_link_cell_joint" type="fixed">
    <origin rpy="0 0 -1.5707963267948966" xyz="0 0 0"/>
    <parent link="robot_link"/>
    <child link="prbt_base_link"/>
  </joint>
  <!-- Specify some standard inertial calculations https://en.wikipedia.org/wiki/List_of_moments_of_inertia -->
  <!-- These make use of xacro's mathematical functionality -->
  <material name="blue">
    <color rgba="0 0.2 1 1"/>
  </material>
  <material name="green">
    <color rgba="0 0.9 0.3 1"/>
  </material>
  <material name="white">
    <color rgba="1 1 1 1"/>
  </material>
  <!--Base plate-->
  <link name="schunk_egp40_base_link">
    <visual>
      <geometry>
        <mesh filename="package://prbt_cell_description/meshes/flange_v3.STL" scale="0.001 0.001 0.001"/>
      </geometry>
      <material name="blue"/>
      <origin rpy="3.141592653589793 0 0" xyz="-0.0325 0.0325 0.015"/>
    </visual>
    <collision>
      <geometry>
        <mesh filename="package://prbt_cell_description/meshes/flange_v3.STL" scale="0.001 0.001 0.001"/>
      </geometry>
      <origin rpy="3.141592653589793 0 0" xyz="-0.0325 0.0325 0.015"/>
    </collision>
  </link>
  <!--Main gripper-->
  <link name="schunk_egp40_body_link">
    <visual>
      <geometry>
        <mesh filename="package://prbt_cell_description/meshes/schunk_egp40_body.STL" scale="0.001 0.001 0.001"/>
      </geometry>
      <origin rpy="1.5707963267948966 0 0" xyz="-0.02 0.013 -0.03655"/>
      <material name="green"/>
    </visual>
    <collision>
      <geometry>
        <mesh filename="package://prbt_cell_description/meshes/schunk_egp40_body.STL" scale="0.001 0.001 0.001"/>
      </geometry>
      <origin rpy="1.5707963267948966 0 0" xyz="-0.02 0.013 -0.03655"/>
    </collision>
    <inertial>
      <origin rpy="1.5707963267948966 0 0" xyz="-0.02 0.013 -0.03655"/>
      <mass value="0.5"/>
      <inertia ixx="0.0002508170833333333" ixy="0.0" ixz="0.0" iyy="0.00028931708333333327" iyz="0.0" izz="9.483333333333334e-05"/>
    </inertial>
  </link>
  <!--Pincer block 1-->
  <link name="schunk_egp40_finger_left_link">
    <visual>
      <geometry>
        <mesh filename="package://prbt_cell_description/meshes/schunk_finger_left.STL" scale="0.001 0.001 0.001"/>
      </geometry>
      <origin rpy="1.5707963267948966 0 0" xyz="-0.02 0.008 -0.07925"/>
      <material name="white"/>
    </visual>
    <collision>
      <geometry>
        <mesh filename="package://prbt_cell_description/meshes/schunk_finger_left.STL" scale="0.001 0.001 0.001"/>
      </geometry>
      <origin rpy="1.5707963267948966 0 0" xyz="-0.02 0.008 -0.07925"/>
    </collision>
    <inertial>
      <origin rpy="1.5707963267948966 0 0" xyz="-0.02 0.008 -0.07925"/>
      <mass value="0.1"/>
      <inertia ixx="3.394083333333333e-06" ixy="0.0" ixz="0.0" iyy="1.4594083333333333e-05" iyz="0.0" izz="1.5466666666666665e-05"/>
    </inertial>
  </link>
  <!--Pincer block 2-->
  <link name="schunk_egp40_finger_right_link">
    <visual>
      <geometry>
        <mesh filename="package://prbt_cell_description/meshes/schunk_finger_right.STL" scale="0.001 0.001 0.001"/>
      </geometry>
      <origin rpy="1.5707963267948966 0 0" xyz="-0.02 0.008 -0.07925"/>
      <material name="blue"/>
    </visual>
    <collision>
      <geometry>
        <mesh filename="package://prbt_cell_description/meshes/schunk_finger_right.STL" scale="0.001 0.001 0.001"/>
      </geometry>
      <origin rpy="1.5707963267948966 0 0" xyz="-0.02 0.008 -0.07925"/>
    </collision>
    <inertial>
      <origin rpy="1.5707963267948966 0 0" xyz="-0.02 0.008 -0.07925"/>
      <mass value="0.1"/>
      <inertia ixx="3.394083333333333e-06" ixy="0.0" ixz="0.0" iyy="1.4594083333333333e-05" iyz="0.0" izz="1.5466666666666665e-05"/>
    </inertial>
  </link>
  <!-- Virtual link for visualizytion and planning-->
  <link name="tool_tip"/>
  <!-- Joints-->
  <joint name="schunk_egp40_body_joint" type="fixed">
    <parent link="schunk_egp40_base_link"/>
    <child link="schunk_egp40_body_link"/>
    <origin rpy="0.0 0.0 0.0" xyz="0.0 0.0 0.05155"/>
  </joint>
  <joint name="schunk_egp40_finger_left_joint" type="fixed">
    <parent link="schunk_egp40_body_link"/>
    <child link="schunk_egp40_finger_left_link"/>
    <origin rpy="0.0 0.0 0.0" xyz="0.0 0.0 0.0427"/>
    <!-- the motion of the pincer is along the X axis -->
    <axis xyz="1 0 0"/>
    <!-- the motion of the pincer is limited to the half of the gripper body length -->
    <limit effort="100" lower="-0.0025" upper="0.0025" velocity="100"/>
  </joint>
  <joint name="schunk_egp40_finger_right_joint" type="fixed">
    <parent link="schunk_egp40_body_link"/>
    <child link="schunk_egp40_finger_right_link"/>
    <origin rpy="0.0 0.0 0.0" xyz="0.0 0.002 0.0427"/>
    <!-- the motion of the pincer is along the X axis -->
    <axis xyz="1 0 0"/>
    <!-- the motion of the pincer is limited to the half of the gripper body length -->
    <limit effort="100" lower="0.0025" upper="-0.0025" velocity="100"/>
  </joint>
  <joint name="schunk_egp40_tip_joint" type="fixed">
    <parent link="schunk_egp40_base_link"/>
    <child link="tool_tip"/>
    <origin rpy="0.0 0.0 0.0" xyz="0 0 0.0884"/>
  </joint>
  <joint name="schunk_egp40_base_joint" type="fixed">
    <parent link="prbt_tool0"/>
    <child link="schunk_egp40_base_link"/>
    <origin rpy="0 0 0" xyz="0 0 0"/>
  </joint>
  <!-- camera body, with origin at bottom screw mount -->
  <joint name="camera_joint" type="fixed">
    <origin rpy="1.52494 -0.0110301 1.57125" xyz="-0.0130762 -0.0636807 0.0292817"/>
    <parent link="prbt_tool0"/>
    <child link="camera_bottom_screw_frame"/>
  </joint>
  <link name="camera_bottom_screw_frame"/>
  <joint name="camera_link_joint" type="fixed">
    <origin rpy="0 0 0" xyz="0.010600000000000002 0.0175 0.0125"/>
    <parent link="camera_bottom_screw_frame"/>
    <child link="camera_link"/>
  </joint>
  <link name="camera_link">
    <visual>
      <!-- the mesh origin is at front plate in between the two infrared camera axes -->
      <origin rpy="1.5707963267948966 0 1.5707963267948966" xyz="0.0043 -0.0175 0"/>
      <geometry>
        <mesh filename="package://realsense2_description/meshes/d435.dae"/>
      </geometry>
    </visual>
    <collision>
      <origin rpy="0 0 0" xyz="0 -0.0175 0"/>
      <geometry>
        <box size="0.02505 0.09 0.025"/>
      </geometry>
    </collision>
    <inertial>
      <!-- The following are not reliable values, and should not be used for modeling -->
      <mass value="0.072"/>
      <origin xyz="0 0 0"/>
      <inertia ixx="0.003881243" ixy="0.0" ixz="0.0" iyy="0.000498940" iyz="0.0" izz="0.003879257"/>
    </inertial>
  </link>
</robot>
